Workbook
Name 、6: #REF!
Name \I: #REF!
Name \P: #REF!
Name _1: #REF!
Name _200901: #REF!
Name _200902: #REF!
Name _20090202: #REF!
Name _200903: #REF!
Name _20090303: #REF!
Name _200904: #REF!
Name _200910: #REF!
Name _200911: #REF!
Name _200912: #REF!
Name _20091201: #REF!
Name _908: #REF!
Name _AfA1: #REF!
Name _AfA10: #REF!
Name _AfA11: #REF!
Name _AfA12: #REF!
Name _AfA2: #REF!
Name _AfA3: #REF!
Name _AfA4: #REF!
Name _AfA5: #REF!
Name _AfA6: #REF!
Name _AfA7: #REF!
Name _AfA8: #REF!
Name _AfA9: #REF!
Name _DAT1: #REF!
Name _DAT10: #REF!
Name _DAT11: #REF!
Name _DAT12: #REF!
Name _DAT14: #REF!
Name _DAT15: #REF!
Name _DAT16: #REF!
Name _DAT17: #REF!
Name _DAT18: #REF!
Name _DAT19: #REF!
Name _DAT2: #REF!
Name _DAT20: #REF!
Name _DAT21: #REF!
Name _DAT22: #REF!
Name _DAT23: #REF!
Name _DAT24: #REF!
Name _DAT25: #REF!
Name _DAT26: #REF!
Name _DAT27: #REF!
Name _DAT28: #REF!
Name _DAT29: #REF!
Name _DAT3: #REF!
Name _DAT30: #REF!
Name _DAT31: #REF!
Name _DAT32: #REF!
Name _DAT33: #REF!
Name _DAT34: #REF!
Name _DAT35: #REF!
Name _DAT36: #REF!
Name _DAT37: #REF!
Name _DAT38: #REF!
Name _DAT39: #REF!
Name _DAT4: #REF!

Sheet 8月
A1: 8月 | R1: 利润（万元） | S1: 边际条件设定（必填项*） | AL1: 注意：此列往右禁止删除列
A2: 单位 | B2: 煤种 | C2: 热值 | D2: 单价 | E2: 价格 (元/吨) | F2: 收到基全水分% | G2: 收到基灰分% | H2: 收到基硫分% | I2: 收到基挥发分% | J2: 配煤比例 | K2: 规划用量 | L2: 可用量 | M2: 最低用量 | N2: 不含运费金额 | O2: 运费 | P2: 运费单价（元/吨） | Q2: 总金额 | R2: =C109 -> 6708.5566 | S2: 项目 | T2: 规划后值 | U2: 边际上限 | V2: 边际下限 | W2: 边际相等
A3: 百矿 | B3: =$B$112 -> 东怀 | C3: =INDEX($B$111:$Q$131,MATCH($B3,$B$111:$B$131,0),MATCH(C$2,$B$111:$Q$111,0)) -> 2482.3501 | D3: {=INDEX($B$111:$Q$131,MATCH($B3,$B$111:$B$131,0),COLUMN($D$2)-1)} -> 0.12049076 | E3: =C3*D3 -> 299.10026 | F3: =INDEX($B$111:$Q$131,MATCH($B3,$B$111:$B$131,0),MATCH(F$2,$B$111:$Q$111,0)) -> 9.05 | G3: =INDEX($B$111:$Q$131,MATCH($B3,$B$111:$B$131,0),MATCH(G$2,$B$111:$Q$111,0)) -> 53.753421 | H3: =INDEX($B$111:$Q$131,MATCH($B3,$B$111:$B$131,0),MATCH(H$2,$B$111:$Q$111,0)) -> 1.5392982 | I3: =INDEX($B$111:$Q$131,MATCH($B3,$B$111:$B$131,0),MATCH(I$2,$B$111:$Q$111,0)) -> 20.240833 | J3: =IFERROR(K3/K18*100,) -> 48.82006 | K3: 16.550016 | L3: {=LOOKUP(1,0/($B$111:$B$131=$B3),$L$111:$L$131)} -> 16.550016 | M3: 0 | N3: =IF(P3>0,INDEX($B$111:$Z$131,MATCH(B3,$B$111:$B$131,0),MATCH($Z$111,$B$111:$Z$111,0))*C3*K3,C3*D3*K3) -> 4724.5373 | O3: =P3*K3 -> 225.57672 | P3: {=INDEX($B$111:$AF$131,MATCH($B3,$B$111:$B$131,0),COLUMN($AA$111)-1)} -> 13.63 | Q3: =SUM(N3:O3) -> 4950.114 | S3: 原煤量 | T3: =$K$18 -> 33.900032 | U3: =W3 -> 33.900032 | V3: =W3 -> 33.900032 | W3: =$AP$164 -> 33.900032 | Z3: 单位 | AA3: 煤种 | AB3: 单价 | AC3: 热值 | AD3: 用量 | AE3: 金额
A4: 发电量 | B4: =$B$113 -> 跃进 | C4: =INDEX($B$111:$Q$131,MATCH($B4,$B$111:$B$131,0),MATCH(C$2,$B$111:$Q$111,0)) -> 1800 | D4: {=INDEX($B$111:$Q$131,MATCH($B4,$B$111:$B$131,0),COLUMN($D$2)-1)} -> 0.11937778 | E4: =C4*D4 -> 214.88 | F4: =INDEX($B$111:$Q$131,MATCH($B4,$B$111:$B$131,0),MATCH(F$2,$B$111:$Q$111,0)) -> 9.9 | G4: =INDEX($B$111:$Q$131,MATCH($B4,$B$111:$B$131,0),MATCH(G$2,$B$111:$Q$111,0)) -> 59.606917 | H4: =INDEX($B$111:$Q$131,MATCH($B4,$B$111:$B$131,0),MATCH(H$2,$B$111:$Q$111,0)) -> 0.41611229 | I4: =INDEX($B$111:$Q$131,MATCH($B4,$B$111:$B$131,0),MATCH(I$2,$B$111:$Q$111,0)) -> 16.798781 | J4: =IFERROR(K4/K18*100,) -> 30.395561 | K4: 10.304105 | L4: {=LOOKUP(1,0/($B$111:$B$131=$B4),$L$111:$L$131)} -> 10.304105 | M4: 0 | N4: =IF(P4>0,INDEX($B$111:$Z$131,MATCH(B4,$B$111:$B$131,0),MATCH($Z$111,$B$111:$Z$111,0))*C4*K4,C4*D4*K4) -> 2040.2128 | O4: =P4*K4 -> 173.93329 | P4: {=INDEX($B$111:$AF$131,MATCH($B4,$B$111:$B$131,0),COLUMN($AA$111)-1)} -> 16.88 | Q4: =SUM(N4:O4) -> 2214.1461 | S4: 原煤量 | T4: =$K$42 -> 25.030456 | U4: =W4 -> 25.030456 | V4: =W4 -> 25.030456 | W4: =$AP$230 -> 25.030456 | AA4: 内购煤 | AB4: =IFERROR(SUMPRODUCT($C$112:$C$115,$D$112:$D$115,$R$112:$R$115)/SUMPRODUCT($C$112:$C$115,$R$112:$R$115),) -> 0.12014458 | AC4: =IFERROR(SUMPRODUCT($C$112:$C$115,$R$112:$R$115)/SUM($R$112:$R$115),) -> 2220.5278 | AD4: =SUM($R$112:$R$115) -> 26.854121 | AE4: =AB4*AC4*AD4 -> 7164.2601
A5: =AP145 -> 42169.721 | B5: =$B$114 -> 州景 | C5: =INDEX($B$111:$Q$131,MATCH($B5,$B$111:$B$131,0),MATCH(C$2,$B$111:$Q$111,0)) -> 0 | D5: {=INDEX($B$111:$Q$131,MATCH($B5,$B$111:$B$131,0),COLUMN($D$2)-1)} -> 0 | E5: =C5*D5 -> 0 | F5: =INDEX($B$111:$Q$131,MATCH($B5,$B$111:$B$131,0),MATCH(F$2,$B$111:$Q$111,0)) -> 15.681 | G5: =INDEX($B$111:$Q$131,MATCH($B5,$B$111:$B$131,0),MATCH(G$2,$B$111:$Q$111,0)) -> 65.22 | H5: =INDEX($B$111:$Q$131,MATCH($B5,$B$111:$B$131,0),MATCH(H$2,$B$111:$Q$111,0)) -> 0.63 | I5: =INDEX($B$111:$Q$131,MATCH($B5,$B$111:$B$131,0),MATCH(I$2,$B$111:$Q$111,0)) -> 58.6 | J5: =IFERROR(K5/K18*100,) -> 0 | K5: 0 | L5: {=LOOKUP(1,0/($B$111:$B$131=$B5),$L$111:$L$131)} -> 0 | M5: 0 | N5: =IF(P5>0,INDEX($B$111:$Z$131,MATCH(B5,$B$111:$B$131,0),MATCH($Z$111,$B$111:$Z$111,0))*C5*K5,C5*D5*K5) -> 0 | O5: =P5*K5 -> 0 | P5: {=INDEX($B$111:$AF$131,MATCH($B5,$B$111:$B$131,0),COLUMN($AA$111)-1)} -> 12.88 | Q5: =SUM(N5:O5) -> 0 | S5: 原煤量 | T5: =$K$66 -> 0 | U5: =W5 -> 0 | V5: =W5 -> 0 | W5: =$AP$296 -> 0 | Z5: 百矿 | AA5: 外购煤 | AB5: =IFERROR(SUMPRODUCT($C$116:$C$130,$D$116:$D$130,$R$116:$R$130)/SUMPRODUCT($C$116:$C$130,$R$116:$R$130),) -> 0.16142174 | AC5: =IFERROR(SUMPRODUCT($C$116:$C$130,$R$116:$R$130)/SUM($R$116:$R$130),) -> 4600 | AD5: =SUM($R$116:$R$130) -> 7.0459113 | AE5: =AB5*AC5*AD5 -> 5231.871
A6: 综合厂用电率 | B6: =$B$115 -> 那荷 | C6: =INDEX($B$111:$Q$131,MATCH($B6,$B$111:$B$131,0),MATCH(C$2,$B$111:$Q$111,0)) -> 0 | D6: {=INDEX($B$111:$Q$131,MATCH($B6,$B$111:$B$131,0),COLUMN($D$2)-1)} -> 0 | E6: =C6*D6 -> 0 | F6: =INDEX($B$111:$Q$131,MATCH($B6,$B$111:$B$131,0),MATCH(F$2,$B$111:$Q$111,0)) -> 8.93 | G6: =INDEX($B$111:$Q$131,MATCH($B6,$B$111:$B$131,0),MATCH(G$2,$B$111:$Q$111,0)) -> 71.46 | H6: =INDEX($B$111:$Q$131,MATCH($B6,$B$111:$B$131,0),MATCH(H$2,$B$111:$Q$111,0)) -> 0.34 | I6: =INDEX($B$111:$Q$131,MATCH($B6,$B$111:$B$131,0),MATCH(I$2,$B$111:$Q$111,0)) -> 56.85 | J6: =IFERROR(K6/K18*100,) -> 0 | K6: 0 | L6: {=LOOKUP(1,0/($B$111:$B$131=$B6),$L$111:$L$131)} -> 0 | M6: 0 | N6: =IF(P6>0,INDEX($B$111:$Z$131,MATCH(B6,$B$111:$B$131,0),MATCH($Z$111,$B$111:$Z$111,0))*C6*K6,C6*D6*K6) -> 0 | O6: =P6*K6 -> 0 | P6: {=INDEX($B$111:$AF$131,MATCH($B6,$B$111:$B$131,0),COLUMN($AA$111)-1)} -> 8.43 | Q6: =SUM(N6:O6) -> 0 | S6: 原煤量 | T6: =$K$90 -> 0 | U6: =W6 -> 0 | V6: =W6 -> 0 | W6: =$AP$362 -> 0 | AA6: 合计 | AB6: =IFERROR(SUMPRODUCT($C$112:$C$130,$D$112:$D$130,$R$112:$R$130)/SUMPRODUCT($C$112:$C$130,$R$112:$R$130),) -> 0.13467978 | AC6: =IFERROR(SUMPRODUCT($C$112:$C$130,$R$112:$R$130)/SUMPRODUCT($R$112:$R$130),) -> 2715.0863 | AD6: =SUM($R$112:$R$130) -> 33.900032 | AE6: =AB6*AC6*AD6 -> 12396.131
A7: 6.0952299 | B7: =$B$116 -> 褐煤2（云）长协 | C7: =INDEX($B$111:$Q$131,MATCH($B7,$B$111:$B$131,0),MATCH(C$2,$B$111:$Q$111,0)) -> 2400 | D7: {=INDEX($B$111:$Q$131,MATCH($B7,$B$111:$B$131,0),COLUMN($D$2)-1)} -> 0.123 | E7: =C7*D7 -> 295.2 | F7: =INDEX($B$111:$Q$131,MATCH($B7,$B$111:$B$131,0),MATCH(F$2,$B$111:$Q$111,0)) -> 19.2 | G7: =INDEX($B$111:$Q$131,MATCH($B7,$B$111:$B$131,0),MATCH(G$2,$B$111:$Q$111,0)) -> 32.974564 | H7: =INDEX($B$111:$Q$131,MATCH($B7,$B$111:$B$131,0),MATCH(H$2,$B$111:$Q$111,0)) -> 0.80500871 | I7: =INDEX($B$111:$Q$131,MATCH($B7,$B$111:$B$131,0),MATCH(I$2,$B$111:$Q$111,0)) -> 28.483232 | J7: =IFERROR(K7/K18*100,) -> 0 | K7: 0 | L7: 0 | M7: 0 | N7: =IF(P7>0,INDEX($B$111:$Z$131,MATCH(B7,$B$111:$B$131,0),MATCH($Z$111,$B$111:$Z$111,0))*C7*K7,C7*D7*K7) -> 0 | O7: =P7*K7 -> 0 | P7: {=INDEX($B$111:$AF$131,MATCH($B7,$B$111:$B$131,0),COLUMN($AA$111)-1)} -> 0 | Q7: =SUM(N7:O7) -> 0 | S7: 配煤热值 | T7: =$C$18 -> 2715.0863 | U7: 4100 | V7: 2629 | AA7: 内购煤 | AB7: =IFERROR(SUMPRODUCT($C$112:$C$115,$D$112:$D$115,$S$112:$S$115)/SUMPRODUCT($C$112:$C$115,$S$112:$S$115),) -> 0 | AC7: =IFERROR(SUMPRODUCT($C$112:$C$115,$S$112:$S$115)/SUM($S$112:$S$115),) -> 0 | AD7: =SUM($S$112:$S$115) -> 0 | AE7: =AB7*AC7*AD7 -> 0
A8: 发电标煤耗 | B8: =$B$117 -> 褐煤3（云）长协 | C8: =INDEX($B$111:$Q$131,MATCH($B8,$B$111:$B$131,0),MATCH(C$2,$B$111:$Q$111,0)) -> 3200 | D8: {=INDEX($B$111:$Q$131,MATCH($B8,$B$111:$B$131,0),COLUMN($D$2)-1)} -> 0.133 | E8: =C8*D8 -> 425.6 | F8: =INDEX($B$111:$Q$131,MATCH($B8,$B$111:$B$131,0),MATCH(F$2,$B$111:$Q$111,0)) -> 19.15 | G8: =INDEX($B$111:$Q$131,MATCH($B8,$B$111:$B$131,0),MATCH(G$2,$B$111:$Q$111,0)) -> 23.873821 | H8: =INDEX($B$111:$Q$131,MATCH($B8,$B$111:$B$131,0),MATCH(H$2,$B$111:$Q$111,0)) -> 0.84706369 | I8: =INDEX($B$111:$Q$131,MATCH($B8,$B$111:$B$131,0),MATCH(I$2,$B$111:$Q$111,0)) -> 30.507667 | J8: =IFERROR(K8/K18*100,) -> 0 | K8: 0 | L8: 0 | M8: 0 | N8: =IF(P8>0,INDEX($B$111:$Z$131,MATCH(B8,$B$111:$B$131,0),MATCH($Z$111,$B$111:$Z$111,0))*C8*K8,C8*D8*K8) -> 0 | O8: =P8*K8 -> 0 | P8: {=INDEX($B$111:$AF$131,MATCH($B8,$B$111:$B$131,0),COLUMN($AA$111)-1)} -> 0 | Q8: =SUM(N8:O8) -> 0 | S8: 配煤热值 | T8: =$C$42 -> 3193.7132 | U8: 3943.47 | V8: 2600 | Z8: 德保 | AA8: 外购煤 | AB8: =IFERROR(SUMPRODUCT($C$116:$C$130,$E$116:$E$130,$S$116:$S$130)/SUMPRODUCT($C$116:$C$130,$S$116:$S$130),) -> 0.13893587 | AC8: =IFERROR(SUMPRODUCT($C$116:$C$130,$S$116:$S$130)/SUM($S$116:$S$130),) -> 3193.7132 | AD8: =SUM($S$116:$S$130) -> 25.030456 | AE8: =AB8*AC8*AD8 -> 11106.547
A9: =AP138 -> 311.80637 | B9: =$B$118 -> 褐煤3（云） | C9: =INDEX($B$111:$Q$131,MATCH($B9,$B$111:$B$131,0),MATCH(C$2,$B$111:$Q$111,0)) -> 3200 | D9: {=INDEX($B$111:$Q$131,MATCH($B9,$B$111:$B$131,0),COLUMN($D$2)-1)} -> 0.1333 | E9: =C9*D9 -> 426.56 | F9: =INDEX($B$111:$Q$131,MATCH($B9,$B$111:$B$131,0),MATCH(F$2,$B$111:$Q$111,0)) -> 19.15 | G9: =INDEX($B$111:$Q$131,MATCH($B9,$B$111:$B$131,0),MATCH(G$2,$B$111:$Q$111,0)) -> 23.873821 | H9: =INDEX($B$111:$Q$131,MATCH($B9,$B$111:$B$131,0),MATCH(H$2,$B$111:$Q$111,0)) -> 0.84706369 | I9: =INDEX($B$111:$Q$131,MATCH($B9,$B$111:$B$131,0),MATCH(I$2,$B$111:$Q$111,0)) -> 30.507667 | J9: =IFERROR(K9/K18*100,) -> 0 | K9: 0 | L9: 0 | M9: 0 | N9: =IF(P9>0,INDEX($B$111:$Z$131,MATCH(B9,$B$111:$B$131,0),MATCH($Z$111,$B$111:$Z$111,0))*C9*K9,C9*D9*K9) -> 0 | O9: =P9*K9 -> 0 | P9: {=INDEX($B$111:$AF$131,MATCH($B9,$B$111:$B$131,0),COLUMN($AA$111)-1)} -> 0 | Q9: =SUM(N9:O9) -> 0 | S9: 配煤热值 | T9: =$C$66 -> 0 | U9: 3756.9351 | V9: 0 | AA9: 合计 | AB9: =IFERROR(SUMPRODUCT($C$112:$C$130,$E$112:$E$130,$S$112:$S$130)/SUMPRODUCT($C$112:$C$130,$S$112:$S$130),) -> 0.13893587 | AC9: =IFERROR(SUMPRODUCT($C$112:$C$130,$S$112:$S$130)/SUMPRODUCT($S$112:$S$130),) -> 3193.7132 | AD9: =SUM($S$112:$S$130) -> 25.030456 | AE9: =AB9*AC9*AD9 -> 11106.547
A10: 自产比例（%） | B10: =$B$119 -> 褐煤32（港1） | C10: =INDEX($B$111:$Q$131,MATCH($B10,$B$111:$B$131,0),MATCH(C$2,$B$111:$Q$111,0)) -> 3200 | D10: {=INDEX($B$111:$Q$131,MATCH($B10,$B$111:$B$131,0),COLUMN($D$2)-1)} -> 0.1687875 | E10: =C10*D10 -> 540.12 | F10: =INDEX($B$111:$Q$131,MATCH($B10,$B$111:$B$131,0),MATCH(F$2,$B$111:$Q$111,0)) -> 32.112709 | G10: =INDEX($B$111:$Q$131,MATCH($B10,$B$111:$B$131,0),MATCH(G$2,$B$111:$Q$111,0)) -> 19.443643 | H10: =INDEX($B$111:$Q$131,MATCH($B10,$B$111:$B$131,0),MATCH(H$2,$B$111:$Q$111,0)) -> 0.77574029 | I10: =INDEX($B$111:$Q$131,MATCH($B10,$B$111:$B$131,0),MATCH(I$2,$B$111:$Q$111,0)) -> 24.82919 | J10: =IFERROR(K10/K18*100,) -> 0 | K10: 0 | L10: 0 | M10: 0 | N10: =IF(P10>0,INDEX($B$111:$Z$131,MATCH(B10,$B$111:$B$131,0),MATCH($Z$111,$B$111:$Z$111,0))*C10*K10,C10*D10*K10) -> 0 | O10: =P10*K10 -> 0 | P10: {=INDEX($B$111:$AF$131,MATCH($B10,$B$111:$B$131,0),COLUMN($AA$111)-1)} -> 95.32 | Q10: =SUM(N10:O10) -> 0 | S10: 配煤热值 | T10: =$C$90 -> 0 | U10: 3756.9351 | V10: 0 | AA10: 内购煤 | AB10: =IFERROR(SUMPRODUCT($C$112:$C$115,$D$112:$D$115,$T$112:$T$115)/SUMPRODUCT($C$112:$C$115,$T$112:$T$115),) -> 0 | AC10: =IFERROR(SUMPRODUCT($C$112:$C$115,$T$112:$T$115)/SUM($T$112:$T$115),) -> 0 | AD10: =SUM($T$112:$T$115) -> 0 | AE10: =AB10*AC10*AD10 -> 0
A11: =(SUMIF($B$3:$B$17,$B$112,$K$3:$K$17)+SUMIF($B$3:$B$17,$B$113,$K$3:$K$17)+SUMIF($B$3:$B$17,$B$114,$K$3:$K$17)+SUMIF($B$3:$B$17,$B$115,$K$3:$K$17))/$K$18*100 -> 79.215621 | B11: =$B$120 -> 褐煤35（港2） | C11: =INDEX($B$111:$Q$131,MATCH($B11,$B$111:$B$131,0),MATCH(C$2,$B$111:$Q$111,0)) -> 3500 | D11: {=INDEX($B$111:$Q$131,MATCH($B11,$B$111:$B$131,0),COLUMN($D$2)-1)} -> 0.17313429 | E11: =C11*D11 -> 605.97 | F11: =INDEX($B$111:$Q$131,MATCH($B11,$B$111:$B$131,0),MATCH(F$2,$B$111:$Q$111,0)) -> 29.814059 | G11: =INDEX($B$111:$Q$131,MATCH($B11,$B$111:$B$131,0),MATCH(G$2,$B$111:$Q$111,0)) -> 17.717186 | H11: =INDEX($B$111:$Q$131,MATCH($B11,$B$111:$B$131,0),MATCH(H$2,$B$111:$Q$111,0)) -> 0.78167601 | I11: =INDEX($B$111:$Q$131,MATCH($B11,$B$111:$B$131,0),MATCH(I$2,$B$111:$Q$111,0)) -> 26.875931 | J11: =IFERROR(K11/K18*100,) -> 0 | K11: 0 | L11: 0 | M11: 0 | N11: =IF(P11>0,INDEX($B$111:$Z$131,MATCH(B11,$B$111:$B$131,0),MATCH($Z$111,$B$111:$Z$111,0))*C11*K11,C11*D11*K11) -> 0 | O11: =P11*K11 -> 0 | P11: {=INDEX($B$111:$AF$131,MATCH($B11,$B$111:$B$131,0),COLUMN($AA$111)-1)} -> 95.32 | Q11: =SUM(N11:O11) -> 0 | S11: 入炉硫量（t/h） | T11: =IFERROR($T$3/SUM($AQ$146,$AR$146)*10000*$H$18/100,) -> 2.5514304 | U11: 4.03 | V11: 0 | Z11: 银海 | AA11: 外购煤 | AB11: =IFERROR(SUMPRODUCT($C$116:$C$130,$D$116:$D$130,$T$116:$T$130)/SUMPRODUCT($C$116:$C$130,$T$116:$T$130),) -> 0 | AC11: =IFERROR(SUMPRODUCT($C$116:$C$130,$T$116:$T$130)/SUM($T$116:$T$130),) -> 0 | AD11: =SUM($T$116:$T$130) -> 0 | AE11: =AB11*AC11*AD11 -> 0
A12: 利润（万元） | B12: =$B$121 -> 褐煤38（港3） | C12: =INDEX($B$111:$Q$131,MATCH($B12,$B$111:$B$131,0),MATCH(C$2,$B$111:$Q$111,0)) -> 3800 | D12: {=INDEX($B$111:$Q$131,MATCH($B12,$B$111:$B$131,0),COLUMN($D$2)-1)} -> 0.16938421 | E12: =C12*D12 -> 643.66 | F12: =INDEX($B$111:$Q$131,MATCH($B12,$B$111:$B$131,0),MATCH(F$2,$B$111:$Q$111,0)) -> 34.679691 | G12: =INDEX($B$111:$Q$131,MATCH($B12,$B$111:$B$131,0),MATCH(G$2,$B$111:$Q$111,0)) -> 8.6727633 | H12: =INDEX($B$111:$Q$131,MATCH($B12,$B$111:$B$131,0),MATCH(H$2,$B$111:$Q$111,0)) -> 0.82970573 | I12: =INDEX($B$111:$Q$131,MATCH($B12,$B$111:$B$131,0),MATCH(I$2,$B$111:$Q$111,0)) -> 28.638706 | J12: =IFERROR(K12/K18*100,) -> 0 | K12: 0 | L12: 0 | M12: 0 | N12: =IF(P12>0,INDEX($B$111:$Z$131,MATCH(B12,$B$111:$B$131,0),MATCH($Z$111,$B$111:$Z$111,0))*C12*K12,C12*D12*K12) -> 0 | O12: =P12*K12 -> 0 | P12: {=INDEX($B$111:$AF$131,MATCH($B12,$B$111:$B$131,0),COLUMN($AA$111)-1)} -> 95.32 | Q12: =SUM(N12:O12) -> 0 | S12: 入炉硫量（t/h） | T12: =IFERROR($T$4/SUM($AQ$212:$AR$212)*10000*$H$42/100,) -> 1.7469984 | U12: 5.06 | V12: 0 | AA12: 合计 | AB12: =IFERROR(SUMPRODUCT($C$112:$C$130,$D$112:$D$130,$T$112:$T$130)/SUMPRODUCT($C$112:$C$130,$T$112:$T$130),) -> 0 | AC12: =IFERROR(SUMPRODUCT($C$112:$C$130,$T$112:$T$130)/SUMPRODUCT($T$112:$T$130),) -> 0 | AD12: =SUM($T$112:$T$130) -> 0 | AE12: =AB12*AC12*AD12 -> 0
A13: =C105 -> 5540.3192 | B13: =$B$122 -> 褐煤46 | C13: =INDEX($B$111:$Q$131,MATCH($B13,$B$111:$B$131,0),MATCH(C$2,$B$111:$Q$111,0)) -> 4600 | D13: {=INDEX($B$111:$Q$131,MATCH($B13,$B$111:$B$131,0),COLUMN($D$2)-1)} -> 0.16142174 | E13: =C13*D13 -> 742.54 | F13: =INDEX($B$111:$Q$131,MATCH($B13,$B$111:$B$131,0),MATCH(F$2,$B$111:$Q$111,0)) -> 23.091665 | G13: =INDEX($B$111:$Q$131,MATCH($B13,$B$111:$B$131,0),MATCH(G$2,$B$111:$Q$111,0)) -> 10.878752 | H13: =INDEX($B$111:$Q$131,MATCH($B13,$B$111:$B$131,0),MATCH(H$2,$B$111:$Q$111,0)) -> 0.20812534 | I13: =INDEX($B$111:$Q$131,MATCH($B13,$B$111:$B$131,0),MATCH(I$2,$B$111:$Q$111,0)) -> 32.849465 | J13: =IFERROR(K13/K18*100,) -> 20.784379 | K13: 7.0459113 | L13: {=LOOKUP(1,0/($B$111:$B$131=$B13),$L$111:$L$131)} -> 100 | M13: 0 | N13: =IF(P13>0,INDEX($B$111:$Z$131,MATCH(B13,$B$111:$B$131,0),MATCH($Z$111,$B$111:$Z$111,0))*C13*K13,C13*D13*K13) -> 4560.2547 | O13: =P13*K13 -> 671.61627 | P13: {=INDEX($B$111:$AF$131,MATCH($B13,$B$111:$B$131,0),COLUMN($AA$111)-1)} -> 95.32 | Q13: =SUM(N13:O13) -> 5231.871 | S13: 入炉硫量（t/h） | T13: =IFERROR($T$5/SUM($AQ$278:$AR$278)*10000*$H$66/100,) -> 0 | U13: 3 | V13: 0 | AA13: 内购煤 | AB13: =IFERROR(SUMPRODUCT($C$112:$C$115,$F$112:$F$115,$U$112:$U$115)/SUMPRODUCT($C$112:$C$115,$U$112:$U$115),) -> 0 | AC13: =IFERROR(SUMPRODUCT($C$112:$C$115,$U$112:$U$115)/SUM($U$112:$U$115),) -> 0 | AD13: =SUM($U$112:$U$115) -> 0 | AE13: =AB13*AC13*AD13 -> 0
A14: 锅炉效率（%） | B14: =$B$123 -> 烟煤55 | C14: =INDEX($B$111:$Q$131,MATCH($B14,$B$111:$B$131,0),MATCH(C$2,$B$111:$Q$111,0)) -> 5500 | D14: {=INDEX($B$111:$Q$131,MATCH($B14,$B$111:$B$131,0),COLUMN($D$2)-1)} -> 0.16633091 | E14: =C14*D14 -> 914.82 | F14: =INDEX($B$111:$Q$131,MATCH($B14,$B$111:$B$131,0),MATCH(F$2,$B$111:$Q$111,0)) -> 10.316451 | G14: =INDEX($B$111:$Q$131,MATCH($B14,$B$111:$B$131,0),MATCH(G$2,$B$111:$Q$111,0)) -> 19.875802 | H14: =INDEX($B$111:$Q$131,MATCH($B14,$B$111:$B$131,0),MATCH(H$2,$B$111:$Q$111,0)) -> 0.47663777 | I14: =INDEX($B$111:$Q$131,MATCH($B14,$B$111:$B$131,0),MATCH(I$2,$B$111:$Q$111,0)) -> 25.313893 | J14: =IFERROR(K14/K18*100,) -> 0 | K14: 0 | L14: {=LOOKUP(1,0/($B$111:$B$131=$B14),$L$111:$L$131)} -> 100 | M14: 0 | N14: =IF(P14>0,INDEX($B$111:$Z$131,MATCH(B14,$B$111:$B$131,0),MATCH($Z$111,$B$111:$Z$111,0))*C14*K14,C14*D14*K14) -> 0 | O14: =P14*K14 -> 0 | P14: {=INDEX($B$111:$AF$131,MATCH($B14,$B$111:$B$131,0),COLUMN($AA$111)-1)} -> 95.32 | Q14: =SUM(N14:O14) -> 0 | S14: 入炉硫量（t/h） | T14: =IFERROR($T$6/SUM($AQ$344:$AR$344)*10000*$H$90/100,) -> 0 | U14: 0.9 | V14: 0 | Z14: 田东 | AA14: 外购煤 | AB14: =IFERROR(SUMPRODUCT($C$116:$C$130,$F$116:$F$130,$U$116:$U$130)/SUMPRODUCT($C$116:$C$130,$U$116:$U$130),) -> 0 | AC14: =IFERROR(SUMPRODUCT($C$116:$C$130,$U$116:$U$130)/SUM($U$116:$U$130),) -> 0 | AD14: =SUM($U$116:$U$130) -> 0 | AE14: =AB14*AC14*AD14 -> 0
A15: =AP139*100 -> 88.88407 | B15: =$B$124 -> 烟煤50备 | C15: =INDEX($B$111:$Q$131,MATCH($B15,$B$111:$B$131,0),MATCH(C$2,$B$111:$Q$111,0)) -> 5000 | D15: {=INDEX($B$111:$Q$131,MATCH($B15,$B$111:$B$131,0),COLUMN($D$2)-1)} -> 0 | E15: =C15*D15 -> 0 | F15: =INDEX($B$111:$Q$131,MATCH($B15,$B$111:$B$131,0),MATCH(F$2,$B$111:$Q$111,0)) -> 0 | G15: =INDEX($B$111:$Q$131,MATCH($B15,$B$111:$B$131,0),MATCH(G$2,$B$111:$Q$111,0)) -> 0 | H15: =INDEX($B$111:$Q$131,MATCH($B15,$B$111:$B$131,0),MATCH(H$2,$B$111:$Q$111,0)) -> 0 | I15: =INDEX($B$111:$Q$131,MATCH($B15,$B$111:$B$131,0),MATCH(I$2,$B$111:$Q$111,0)) -> 0 | J15: =IFERROR(K15/K18*100,) -> 0 | K15: 0 | L15: {=LOOKUP(1,0/($B$111:$B$131=$B15),$L$111:$L$131)} -> 0 | M15: 0 | N15: =IF(P15>0,INDEX($B$111:$Z$131,MATCH(B15,$B$111:$B$131,0),MATCH($Z$111,$B$111:$Z$111,0))*C15*K15,C15*D15*K15) -> 0 | O15: =P15*K15 -> 0 | P15: {=INDEX($B$111:$AF$131,MATCH($B15,$B$111:$B$131,0),COLUMN($AA$111)-1)} -> 0 | Q15: =SUM(N15:O15) -> 0 | S15: 矸石退税 | T15: =IFERROR(((SUMIF($B$3:$B$17,$B$112,$K$3:$K$17)+SUMIF($B$3:$B$17,$B$113,$K$3:$K$17)+SUMIF($B$3:$B$17,$B$114,$K$3:$K$17)+SUMIF($B$3:$B$17,$B$115,$K$3:$K$17))*(1-13%)+SUMIF($B$3:$B$17,$B$116,$K$3:$K$17)+SUMIF($B$3:$B$17,$B$117,$K$3:$K$17))/$K$18*100,) -> 68.91759 | U15: 100 | V15: 60 | AA15: 合计 | AB15: =IFERROR(SUMPRODUCT($C$112:$C$130,$F$112:$F$130,$U$112:$U$130)/SUMPRODUCT($C$112:$C$130,$U$112:$U$130),) -> 0 | AC15: =IFERROR(SUMPRODUCT($C$112:$C$130,$U$112:$U$130)/SUMPRODUCT($U$112:$U$130),) -> 0 | AD15: =SUM($U$112:$U$130) -> 0 | AE15: =AB15*AC15*AD15 -> 0
A16: 汽机热耗率 | B16: =$B$125 -> 烟煤55备 | C16: =INDEX($B$111:$Q$131,MATCH($B16,$B$111:$B$131,0),MATCH(C$2,$B$111:$Q$111,0)) -> 5500 | D16: {=INDEX($B$111:$Q$131,MATCH($B16,$B$111:$B$131,0),COLUMN($D$2)-1)} -> 0 | E16: =C16*D16 -> 0 | F16: =INDEX($B$111:$Q$131,MATCH($B16,$B$111:$B$131,0),MATCH(F$2,$B$111:$Q$111,0)) -> 0 | G16: =INDEX($B$111:$Q$131,MATCH($B16,$B$111:$B$131,0),MATCH(G$2,$B$111:$Q$111,0)) -> 0 | H16: =INDEX($B$111:$Q$131,MATCH($B16,$B$111:$B$131,0),MATCH(H$2,$B$111:$Q$111,0)) -> 0 | I16: =INDEX($B$111:$Q$131,MATCH($B16,$B$111:$B$131,0),MATCH(I$2,$B$111:$Q$111,0)) -> 0 | J16: =IFERROR(K16/K18*100,) -> 0 | K16: 0 | L16: {=LOOKUP(1,0/($B$111:$B$131=$B16),$L$111:$L$131)} -> 0 | M16: 0 | N16: =IF(P16>0,INDEX($B$111:$Z$131,MATCH(B16,$B$111:$B$131,0),MATCH($Z$111,$B$111:$Z$111,0))*C16*K16,C16*D16*K16) -> 0 | O16: =P16*K16 -> 0 | P16: {=INDEX($B$111:$AF$131,MATCH($B16,$B$111:$B$131,0),COLUMN($AA$111)-1)} -> 0 | Q16: =SUM(N16:O16) -> 0 | S16: 矸石退税 | T16: =IFERROR(((SUMIF($B$27:$B$41,$B$112,$K$27:$K$41)+SUMIF($B$27:$B$41,$B$113,$K$27:$K$41)+SUMIF($B$27:$B$41,$B$114,$K$27:$K$41)+SUMIF($B$27:$B$41,$B$115,$K$27:$K$41))*(1-13%)+SUMIF($B$27:$B$41,$B$116,$K$27:$K$41)+SUMIF($B$27:$B$41,$B$117,$K$27:$K$41))/$K$42*100,) -> 47.941596 | U16: 100 | V16: 0 | AA16: 内购煤 | AB16: =(AB4*AC4*AD4+AB7*AC7*AD7+AB10*AC10*AD10+AB13*AC13*AD13)/(AC4*AD4+AC7*AD7+AC10*AD10+AC13*AD13) -> 0.12014458 | AC16: =(AC4*AD4+AC7*AD7+AC10*AD10+AC13*AD13)/(AD4+AD7+AD10+AD13) -> 2220.5278 | AD16: =SUM($K$112:$K$115) -> 26.854121 | AE16: =AB16*AC16*AD16 -> 7164.2601
A17: =AP140 -> 8025.02 | B17: =$B$127 -> 石油焦 | C17: =INDEX($B$111:$Q$131,MATCH($B17,$B$111:$B$131,0),MATCH(C$2,$B$111:$Q$111,0)) -> 7256.4478 | D17: {=INDEX($B$111:$Q$131,MATCH($B17,$B$111:$B$131,0),COLUMN($D$2)-1)} -> 0 | E17: =C17*D17 -> 0 | F17: =INDEX($B$111:$Q$131,MATCH($B17,$B$111:$B$131,0),MATCH(F$2,$B$111:$Q$111,0)) -> 0 | G17: =INDEX($B$111:$Q$131,MATCH($B17,$B$111:$B$131,0),MATCH(G$2,$B$111:$Q$111,0)) -> 0 | H17: =INDEX($B$111:$Q$131,MATCH($B17,$B$111:$B$131,0),MATCH(H$2,$B$111:$Q$111,0)) -> 0 | I17: =INDEX($B$111:$Q$131,MATCH($B17,$B$111:$B$131,0),MATCH(I$2,$B$111:$Q$111,0)) -> 0 | J17: =IFERROR(K17/K18*100,) -> 0 | K17: 0 | L17: {=LOOKUP(1,0/($B$111:$B$131=$B17),$L$111:$L$131)} -> 0 | M17: 0 | N17: =IF(P17>0,INDEX($B$111:$Z$131,MATCH(B17,$B$111:$B$131,0),MATCH($Z$111,$B$111:$Z$111,0))*C17*K17,C17*D17*K17) -> 0 | O17: =P17*K17 -> 0 | P17: {=INDEX($B$111:$AF$131,MATCH($B17,$B$111:$B$131,0),COLUMN($AA$111)-1)} -> 0 | Q17: =SUM(N17:O17) -> 0 | S17: 矸石退税 | T17: =IFERROR(((SUMIF($B$51:$B$65,$B$112,$K$51:$K$65)+SUMIF($B$51:$B$65,$B$113,$K$51:$K$65)+SUMIF($B$51:$B$65,$B$114,$K$51:$K$65)+SUMIF($B$51:$B$65,$B$115,$K$51:$K$65))*(1-13%)+SUMIF($B$51:$B$65,$B$116,$K$51:$K$65)+SUMIF($B$51:$B$65,$B$117,$K$51:$K$65))/$K$66*100,) -> 0 | U17: 100 | V17: 0 | Z17: 业务部 | AA17: 外购煤 | AB17: =(AB5*AC5*AD5+AB8*AC8*AD8+AB11*AC11*AD11+AB14*AC14*AD14)/(AC5*AD5+AC8*AD8+AC11*AD11+AC14*AD14) -> 0.14542261 | AC17: =(AC5*AD5+AC8*AD8+AC11*AD11+AC14*AD14)/(AD5+AD8+AD11+AD14) -> 3502.6189 | AD17: =SUM($K$116:$K$130) -> 32.076367 | AE17: =AB17*AC17*AD17 -> 16338.418
B18: 加权平均 | C18: =IFERROR(SUMPRODUCT(C3:C17,K3:K17)/SUM(K3:K17),) -> 2715.0863 | D18: =IFERROR(SUMPRODUCT(C3:C17,D3:D17,K3:K17)/SUMPRODUCT(C3:C17,K3:K17),) -> 0.13467978 | E18: =IFERROR(SUMPRODUCT(C3:C17,E3:E17,K3:K17)/SUMPRODUCT(C3:C17,K3:K17),) -> 438.28033 | F18: =IFERROR(SUMPRODUCT(F3:F17,K3:K17)/SUM(K3:K17),) -> 12.226835 | G18: =IFERROR(SUMPRODUCT(G3:G17,K3:K17)/SUM(K3:K17),) -> 46.62139 | H18: =IFERROR(SUMPRODUCT(H3:H17,K3:K17)/SUM(K3:K17),) -> 0.92122355 | I18: =IFERROR(SUMPRODUCT(I3:I17,K3:K17)/SUM(K3:K17),) -> 21.815228 | J18: =IFERROR(SUM(J3:J17),) -> 100 | K18: =IFERROR(SUM(K3:K17),) -> 33.900032 | L18: =SUM(L3:L17) -> 226.85412 | M18: =SUM(M3:M17) -> 0 | N18: =SUM(N3:N17) -> 11325.005 | O18: =SUM(O3:O17) -> 1071.1263 | P18: =IFERROR(SUMPRODUCT(P3:P17,K3:K17)/SUM(K3:K17),) -> 31.596615 | Q18: =SUM(Q3:Q17) -> 12396.131 | R18: =SUM(R3:R17) -> 0 | S18: 矸石退税 | T18: =IFERROR(((SUMIF($B$75:$B$89,$B$112,$K$75:$K$89)+SUMIF($B$75:$B$89,$B$113,$K$75:$K$89)+SUMIF($B$75:$B$89,$B$114,$K$75:$K$89)+SUMIF($B$75:$B$89,$B$115,$K$75:$K$89))*(1-13%)+SUMIF($B$75:$B$89,$B$116,$K$75:$K$89)+SUMIF($B$75:$B$89,$B$117,$K$75:$K$89))/$K$90*100,) -> 0 | U18: 100 | V18: 0 | AA18: 合计 | AB18: =(AB6*AC6*AD6+AB9*AC9*AD9+AB12*AC12*AD12+AB15*AC15*AD15)/(AC6*AD6+AC9*AD9+AC12*AD12+AC15*AD15) -> 0.13665809 | AC18: =(AC6*AD6+AC9*AD9+AC12*AD12+AC15*AD15)/(AD6+AD9+AD12+AD15) -> 2918.3809 | AD18: =SUM($K$112:$K$130) -> 58.930488 | AE18: =AB18*AC18*AD18 -> 23502.678
B19: 炉灰占比% | C19: =T$47 -> 40 | D19: 炉灰产量（万吨） | E19: =$K18*$G18/100*C19/100 -> 6.3218665 | F19: 炉灰销售% | G19: =T$51 -> 40 | H19: 炉灰销量（万吨） | I19: =E19*G19/100 -> 2.5287466 | J19: 炉灰价格（元/吨） | K19: =T$54 -> -20 | L19: 炉灰收入（万元） | M19: =I19*K19 -> -50.574932 | N19: 炉灰税率% | O19: 13 | P19: 税后金额（万元） | Q19: =M19/(1+O19/100) -> -44.756577 | S19: 入炉煤量（t/h） | T19: =IFERROR($T$3/SUM($AQ$146,$AR$146)*10000,) -> 276.96105 | U19: 300 | V19: 0
B20: 炉渣占比% | C20: =100-C19 -> 60 | D20: 炉渣产量（万吨） | E20: =$K18*$G18/100*C20/100 -> 9.4827998 | F20: 炉渣销售% | G20: =T$52 -> 45 | H20: 炉渣销量（万吨） | I20: =E20*G20/100 -> 4.2672599 | J20: 炉渣价格（元/吨） | K20: =T$55 -> -8 | L20: 炉渣收入（万元） | M20: =I20*K20 -> -34.138079 | N20: 炉渣税率% | O20: 13 | P20: 税后金额（万元） | Q20: =M20/(1+O20/100) -> -30.21069 | S20: 入炉煤量（t/h） | T20: =IFERROR($T$4/SUM($AQ$212:$AR$212)*10000,) -> 248.31801 | U20: 300 | V20: 0 | Z20: 项目 | AA20: 单位 | AB20: 百矿 | AC20: 德保 | AD20: 银海 | AE20: 田东 | AF20: 合计
B21: 钙硫比 | C21: =T$49 -> 4.35 | D21: 石膏产量（万吨） | E21: =C22*I25 -> 2.649043 | F21: 石膏销售% | G21: =T$53 -> 38 | H21: 石膏销量（万吨） | I21: =E21*G21/100 -> 1.0066363 | J21: 石膏价格（元/吨） | K21: =T$56 -> -5 | L21: 石膏收入（万元） | M21: =I21*K21 -> -5.0331817 | N21: 硫酸铵税率% | O21: 13 | P21: 税后金额（万元） | Q21: =M21/(1+O21/100) -> -4.4541431 | S21: 入炉煤量（t/h） | T21: =IFERROR($T$5/SUM($AQ$278:$AR$278)*10000,) -> 0 | U21: 150 | V21: 0 | Z21: 炉灰产量 | AA21: 万吨 | AB21: =E19 -> 6.3218665 | AC21: =E43 -> 5.5269738 | AD21: =E67 -> 0 | AE21: =E91 -> 0 | AF21: =SUM(AB21:AE21) -> 11.84884
B22: 石膏石粉比 | C22: =T$50 -> 1.95 | D22: 销售蒸汽（万吨） | E22: =T$62 -> 0 | F22: 炉灰调湿比例% | G22: =T64 -> 25 | H22: 炉灰倒运量（万吨） | I22: =(E19-I19)/(1-G22/100) -> 5.0574932 | J22: 炉灰倒运单价（元/吨） | K22: =T$57 -> 7.9 | L22: 炉灰倒运费（万元） | M22: =I22*K22 -> 39.954197 | N22: 炉灰倒运税率% | O22: 6 | P22: 税后金额（万元） | Q22: =M22/(1+O22/100) -> 37.692638 | S22: 入炉煤量（t/h） | T22: =IFERROR($T$6/SUM($AQ$344:$AR$344)*10000,) -> 0 | U22: 150 | V22: 0 | Z22: 炉渣产量 | AA22: 万吨 | AB22: =E20 -> 9.4827998 | AC22: =E44 -> 0.6141082 | AD22: =E68 -> 0 | AE22: =E92 -> 0 | AF22: =SUM(AB22:AE22) -> 10.096908
D23: 蒸汽单价（元/吨） | E23: =T$63 -> 168 | F23: 炉渣调湿比例% | G23: =T65 -> 25 | H23: 炉渣倒运量（万吨） | I23: =(E20-I20)/(1-G23/100) -> 6.9540532 | J23: 炉渣倒运单价（元/吨） | K23: =T$58 -> 7.9 | L23: 炉渣倒运费（万元） | M23: =I23*K23 -> 54.93702 | N23: 炉渣倒运税率% | O23: 6 | P23: 税后金额（万元） | Q23: =M23/(1+O23/100) -> 51.827378 | S23: 灰渣总量（t/h） | T23: =IFERROR($T$3/SUM($AQ$146,$AR$146)*10000*$G$18/100,) -> 129.12309 | U23: 150 | V23: 0 | Z23: 石膏产量 | AA23: 万吨 | AB23: =E21 -> 2.649043 | AC23: =E45 -> 0.48809617 | AD23: =E69 -> 0 | AF23: =SUM(AB23:AE23) -> 3.1371392
D24: 蒸汽收入（万元） | E24: =E22*E23 -> 0 | H24: 石膏倒运量（万吨） | I24: =E21-I21 -> 1.6424067 | J24: 石膏倒运单价（元/吨） | K24: =T$59 -> 7.9 | L24: 石膏倒运费（万元） | M24: =I24*K24 -> 12.975013 | N24: 石膏运税率% | O24: 6 | P24: 税后金额（万元） | Q24: =M24/(1+O24/100) -> 12.240578 | S24: 灰渣总量（t/h） | T24: =IFERROR($T$4/SUM($AQ$212:$AR$212)*10000*$G$42/100,) -> 60.923432 | U24: 104.57 | V24: 0 | Z24: 硫酸铵产量 | AA24: 万吨 | AE24: =E93 -> 0 | AF24: =SUM(AB24:AE24) -> 0
D25: 税率% | E25: 9 | H25: 石粉耗用（万吨） | I25: =H18/100*K18*C21 -> 1.3584836 | J25: 石粉单价（元/吨） | K25: =T$60 -> 67 | L25: 石粉费用（万元） | M25: =I25*K25 -> 91.018401 | N25: 石粉税率% | O25: 13 | P25: 税后金额（万元） | Q25: =M25/(1+O25/100) -> 80.547258 | S25: 灰渣总量（t/h） | T25: =IFERROR($T$5/SUM($AQ$278:$AR$278)*10000*$G$66/100,) -> 0 | U25: 43.88 | V25: 0 | Z25: 炉灰销量 | AA25: 万吨 | AB25: =I19 -> 2.5287466 | AC25: =I43 -> 1.4253188 | AD25: =I67 -> 0 | AE25: =I91 -> 0 | AF25: =SUM(AB25:AE25) -> 3.9540654
D26: 税后蒸汽收入（万元） | E26: =E24/(1+E25/100) -> 0 | H26: 尿素耗用（万吨） | I26: =(0.016*I18+0.09)/100*K18*12%/85%*2.354*0 -> 0 | J26: 尿素单价（元/吨） | K26: =T$61 -> 2200 | L26: 尿素费用（万元） | M26: =I26*K26 -> 0 | N26: 尿素税率% | O26: 13 | P26: 税后金额（万元） | Q26: =M26/(1+O26/100) -> 0 | S26: 灰渣总量（t/h） | T26: =IFERROR($T$6/SUM($AQ$344:$AR$344)*10000*$G$90/100,) -> 0 | U26: 41.99 | V26: 0 | Z26: 炉渣销量 | AA26: 万吨 | AB26: =I20 -> 4.2672599 | AC26: =I44 -> 0.3563297 | AD26: =I68 -> 0 | AE26: =I92 -> 0 | AF26: =SUM(AB26:AE26) -> 4.6235896
A27: 德保 | B27: =$B$112 -> 东怀 | C27: =INDEX($B$111:$Q$131,MATCH($B27,$B$111:$B$131,0),MATCH(C$2,$B$111:$Q$111,0)) -> 2482.3501 | D27: {=INDEX($B$111:$Q$131,MATCH($B27,$B$111:$B$131,0),COLUMN($D$2))} -> 0.12909954 | E27: =C27*D27 -> 320.47026 | F27: =INDEX($B$111:$Q$131,MATCH($B27,$B$111:$B$131,0),MATCH(F$2,$B$111:$Q$111,0)) -> 9.05 | G27: =INDEX($B$111:$Q$131,MATCH($B27,$B$111:$B$131,0),MATCH(G$2,$B$111:$Q$111,0)) -> 53.753421 | H27: =INDEX($B$111:$Q$131,MATCH($B27,$B$111:$B$131,0),MATCH(H$2,$B$111:$Q$111,0)) -> 1.5392982 | I27: =INDEX($B$111:$Q$131,MATCH($B27,$B$111:$B$131,0),MATCH(I$2,$B$111:$Q$111,0)) -> 20.240833 | J27: =IFERROR(K27/K42*100,) -> 0 | K27: 0 | L27: 0 | M27: 0 | N27: =IF(P27>0,INDEX($B$111:$Z$131,MATCH(B27,$B$111:$B$131,0),MATCH($Z$111,$B$111:$Z$111,0))*C27*K27,C27*D27*K27) -> 0 | O27: =P27*K27 -> 0 | P27: {=INDEX($B$111:$AF$131,MATCH($B27,$B$111:$B$131,0),COLUMN($AA$111))} -> 35 | Q27: =SUM(N27:O27) -> 0 | S27: 石油焦比例（%） | T27: {=SUMPRODUCT((B3:B17="石油焦")*1,J3:J17)} -> 0 | U27: 5 | V27: 0 | Z27: 石膏销量 | AA27: 万吨 | AB27: =I21 -> 1.0066363 | AC27: =I45 -> 0.28767855 | AD27: =I69 -> 0 | AF27: =SUM(AB27:AE27) -> 1.2943149
A28: 发电量 | B28: =$B$113 -> 跃进 | C28: =INDEX($B$111:$Q$131,MATCH($B28,$B$111:$B$131,0),MATCH(C$2,$B$111:$Q$111,0)) -> 1800 | D28: {=INDEX($B$111:$Q$131,MATCH($B28,$B$111:$B$131,0),COLUMN($D$2))} -> 0.13777778 | E28: =C28*D28 -> 248 | F28: =INDEX($B$111:$Q$131,MATCH($B28,$B$111:$B$131,0),MATCH(F$2,$B$111:$Q$111,0)) -> 9.9 | G28: =INDEX($B$111:$Q$131,MATCH($B28,$B$111:$B$131,0),MATCH(G$2,$B$111:$Q$111,0)) -> 59.606917 | H28: =INDEX($B$111:$Q$131,MATCH($B28,$B$111:$B$131,0),MATCH(H$2,$B$111:$Q$111,0)) -> 0.41611229 | I28: =INDEX($B$111:$Q$131,MATCH($B28,$B$111:$B$131,0),MATCH(I$2,$B$111:$Q$111,0)) -> 16.798781 | J28: =IFERROR(K28/K42*100,) -> 0 | K28: 0 | L28: 0 | M28: 0 | N28: =IF(P28>0,INDEX($B$111:$Z$131,MATCH(B28,$B$111:$B$131,0),MATCH($Z$111,$B$111:$Z$111,0))*C28*K28,C28*D28*K28) -> 0 | O28: =P28*K28 -> 0 | P28: {=INDEX($B$111:$AF$131,MATCH($B28,$B$111:$B$131,0),COLUMN($AA$111))} -> 50 | Q28: =SUM(N28:O28) -> 0 | S28: 石油焦比例（%） | T28: {=SUMPRODUCT((B27:B41="石油焦")*1,J27:J41)} -> 0 | U28: 5 | V28: 0 | Z28: 硫酸铵销量 | AA28: 万吨 | AE28: =I93 -> 0 | AF28: =SUM(AB28:AE28) -> 0
A29: =AP211 -> 38174.131 | B29: =$B$114 -> 州景 | C29: =INDEX($B$111:$Q$131,MATCH($B29,$B$111:$B$131,0),MATCH(C$2,$B$111:$Q$111,0)) -> 0 | D29: {=INDEX($B$111:$Q$131,MATCH($B29,$B$111:$B$131,0),COLUMN($D$2))} -> 0 | E29: =C29*D29 -> 0 | F29: =INDEX($B$111:$Q$131,MATCH($B29,$B$111:$B$131,0),MATCH(F$2,$B$111:$Q$111,0)) -> 15.681 | G29: =INDEX($B$111:$Q$131,MATCH($B29,$B$111:$B$131,0),MATCH(G$2,$B$111:$Q$111,0)) -> 65.22 | H29: =INDEX($B$111:$Q$131,MATCH($B29,$B$111:$B$131,0),MATCH(H$2,$B$111:$Q$111,0)) -> 0.63 | I29: =INDEX($B$111:$Q$131,MATCH($B29,$B$111:$B$131,0),MATCH(I$2,$B$111:$Q$111,0)) -> 58.6 | J29: =IFERROR(K29/K42*100,) -> 0 | K29: 0 | L29: 0 | M29: 0 | N29: =IF(P29>0,INDEX($B$111:$Z$131,MATCH(B29,$B$111:$B$131,0),MATCH($Z$111,$B$111:$Z$111,0))*C29*K29,C29*D29*K29) -> 0 | O29: =P29*K29 -> 0 | P29: {=INDEX($B$111:$AF$131,MATCH($B29,$B$111:$B$131,0),COLUMN($AA$111))} -> 35 | Q29: =SUM(N29:O29) -> 0 | S29: 石油焦比例（%） | T29: {=SUMPRODUCT((B51:B65="石油焦")*1,J51:J65)} -> 0 | U29: 5 | V29: 0 | Z29: 蒸汽销量 | AA29: 万吨 | AB29: =E22 -> 0 | AC29: =E46 -> 0 | AD29: =E70 -> 0 | AE29: =E94 -> 0 | AF29: =SUM(AB29:AE29) -> 0
A30: 综合厂用电率 | B30: =$B$115 -> 那荷 | C30: =INDEX($B$111:$Q$131,MATCH($B30,$B$111:$B$131,0),MATCH(C$2,$B$111:$Q$111,0)) -> 0 | D30: {=INDEX($B$111:$Q$131,MATCH($B30,$B$111:$B$131,0),COLUMN($D$2))} -> 0 | E30: =C30*D30 -> 0 | F30: =INDEX($B$111:$Q$131,MATCH($B30,$B$111:$B$131,0),MATCH(F$2,$B$111:$Q$111,0)) -> 8.93 | G30: =INDEX($B$111:$Q$131,MATCH($B30,$B$111:$B$131,0),MATCH(G$2,$B$111:$Q$111,0)) -> 71.46 | H30: =INDEX($B$111:$Q$131,MATCH($B30,$B$111:$B$131,0),MATCH(H$2,$B$111:$Q$111,0)) -> 0.34 | I30: =INDEX($B$111:$Q$131,MATCH($B30,$B$111:$B$131,0),MATCH(I$2,$B$111:$Q$111,0)) -> 56.85 | J30: =IFERROR(K30/K42*100,) -> 0 | K30: 0 | L30: 0 | M30: 0 | N30: =IF(P30>0,INDEX($B$111:$Z$131,MATCH(B30,$B$111:$B$131,0),MATCH($Z$111,$B$111:$Z$111,0))*C30*K30,C30*D30*K30) -> 0 | O30: =P30*K30 -> 0 | P30: {=INDEX($B$111:$AF$131,MATCH($B30,$B$111:$B$131,0),COLUMN($AA$111))} -> 50 | Q30: =SUM(N30:O30) -> 0 | S30: 石油焦比例（%） | T30: {=SUMPRODUCT((B75:B89="石油焦")*1,J75:J89)} -> 0 | U30: 5 | V30: 0 | Z30: 炉灰倒运量 | AA30: 万吨 | AB30: =I22 -> 5.0574932 | AC30: =I46 -> 5.4688733 | AD30: =I70 -> 0 | AE30: =I94 -> 0 | AF30: =SUM(AB30:AE30) -> 10.526367
A31: 6.2584823 | B31: =$B$116 -> 褐煤2（云）长协 | C31: =INDEX($B$111:$Q$131,MATCH($B31,$B$111:$B$131,0),MATCH(C$2,$B$111:$Q$111,0)) -> 2400 | D31: {=INDEX($B$111:$Q$131,MATCH($B31,$B$111:$B$131,0),COLUMN($D$2))} -> 0.123 | E31: =C31*D31 -> 295.2 | F31: =INDEX($B$111:$Q$131,MATCH($B31,$B$111:$B$131,0),MATCH(F$2,$B$111:$Q$111,0)) -> 19.2 | G31: =INDEX($B$111:$Q$131,MATCH($B31,$B$111:$B$131,0),MATCH(G$2,$B$111:$Q$111,0)) -> 32.974564 | H31: =INDEX($B$111:$Q$131,MATCH($B31,$B$111:$B$131,0),MATCH(H$2,$B$111:$Q$111,0)) -> 0.80500871 | I31: =INDEX($B$111:$Q$131,MATCH($B31,$B$111:$B$131,0),MATCH(I$2,$B$111:$Q$111,0)) -> 28.483232 | J31: =IFERROR(K31/K42*100,) -> 35.956197 | K31: 9 | L31: {=LOOKUP(1,0/($B$111:$B$131=$B31),$L$111:$L$131)} -> 9 | M31: 0 | N31: =IF(P31>0,INDEX($B$111:$Z$131,MATCH(B31,$B$111:$B$131,0),MATCH($Z$111,$B$111:$Z$111,0))*C31*K31,C31*D31*K31) -> 2656.8 | O31: =P31*K31 -> 0 | P31: {=INDEX($B$111:$AF$131,MATCH($B31,$B$111:$B$131,0),COLUMN($AA$111))} -> 0 | Q31: =SUM(N31:O31) -> 2656.8 | S31: 水分% | T31: =F18 -> 12.226835 | U31: =IF(A5>0,25,0) -> 25 | V31: 0 | Z31: 炉渣倒运量 | AA31: 万吨 | AB31: =I23 -> 6.9540532 | AC31: =I47 -> 0.34370466 | AD31: =I71 -> 0 | AE31: =I95 -> 0 | AF31: =SUM(AB31:AE31) -> 7.2977579
A32: 发电标煤耗 | B32: =$B$117 -> 褐煤3（云）长协 | C32: =INDEX($B$111:$Q$131,MATCH($B32,$B$111:$B$131,0),MATCH(C$2,$B$111:$Q$111,0)) -> 3200 | D32: {=INDEX($B$111:$Q$131,MATCH($B32,$B$111:$B$131,0),COLUMN($D$2))} -> 0.133 | E32: =C32*D32 -> 425.6 | F32: =INDEX($B$111:$Q$131,MATCH($B32,$B$111:$B$131,0),MATCH(F$2,$B$111:$Q$111,0)) -> 19.15 | G32: =INDEX($B$111:$Q$131,MATCH($B32,$B$111:$B$131,0),MATCH(G$2,$B$111:$Q$111,0)) -> 23.873821 | H32: =INDEX($B$111:$Q$131,MATCH($B32,$B$111:$B$131,0),MATCH(H$2,$B$111:$Q$111,0)) -> 0.84706369 | I32: =INDEX($B$111:$Q$131,MATCH($B32,$B$111:$B$131,0),MATCH(I$2,$B$111:$Q$111,0)) -> 30.507667 | J32: =IFERROR(K32/K42*100,) -> 11.985399 | K32: 3 | L32: {=LOOKUP(1,0/($B$111:$B$131=$B32),$L$111:$L$131)} -> 3 | M32: 0 | N32: =IF(P32>0,INDEX($B$111:$Z$131,MATCH(B32,$B$111:$B$131,0),MATCH($Z$111,$B$111:$Z$111,0))*C32*K32,C32*D32*K32) -> 1276.8 | O32: =P32*K32 -> 0 | P32: {=INDEX($B$111:$AF$131,MATCH($B32,$B$111:$B$131,0),COLUMN($AA$111))} -> 0 | Q32: =SUM(N32:O32) -> 1276.8 | S32: 水分% | T32: =F42 -> 19.960148 | U32: =IF(A29>0,35,0) -> 35 | V32: 0 | Z32: 石膏倒运量 | AA32: 万吨 | AB32: =I24 -> 1.6424067 | AC32: =I48 -> 0.20041762 | AD32: =I72 -> 0 | AF32: =SUM(AB32:AE32) -> 1.8428243
A33: =AP204 -> 299.15583 | B33: =$B$118 -> 褐煤3（云） | C33: =INDEX($B$111:$Q$131,MATCH($B33,$B$111:$B$131,0),MATCH(C$2,$B$111:$Q$111,0)) -> 3200 | D33: {=INDEX($B$111:$Q$131,MATCH($B33,$B$111:$B$131,0),COLUMN($D$2))} -> 0.1333 | E33: =C33*D33 -> 426.56 | F33: =INDEX($B$111:$Q$131,MATCH($B33,$B$111:$B$131,0),MATCH(F$2,$B$111:$Q$111,0)) -> 19.15 | G33: =INDEX($B$111:$Q$131,MATCH($B33,$B$111:$B$131,0),MATCH(G$2,$B$111:$Q$111,0)) -> 23.873821 | H33: =INDEX($B$111:$Q$131,MATCH($B33,$B$111:$B$131,0),MATCH(H$2,$B$111:$Q$111,0)) -> 0.84706369 | I33: =INDEX($B$111:$Q$131,MATCH($B33,$B$111:$B$131,0),MATCH(I$2,$B$111:$Q$111,0)) -> 30.507667 | J33: =IFERROR(K33/K42*100,) -> 31.961064 | K33: 8 | L33: {=LOOKUP(1,0/($B$111:$B$131=$B33),$L$111:$L$131)} -> 8 | M33: 0 | N33: =IF(P33>0,INDEX($B$111:$Z$131,MATCH(B33,$B$111:$B$131,0),MATCH($Z$111,$B$111:$Z$111,0))*C33*K33,C33*D33*K33) -> 3412.48 | O33: =P33*K33 -> 0 | P33: {=INDEX($B$111:$AF$131,MATCH($B33,$B$111:$B$131,0),COLUMN($AA$111))} -> 0 | Q33: =SUM(N33:O33) -> 3412.48 | S33: 水分% | T33: =F66 -> 0 | U33: =IF(A53>0,30,0) -> 0 | V33: 0 | Z33: 硫酸铵库存 | AA33: 万吨 | AB33: =E26 -> 0 | AE33: =I96 -> 0 | AF33: =SUM(AB33:AE33) -> 0
A34: 自产比例（%） | B34: =$B$119 -> 褐煤32（港1） | C34: =INDEX($B$111:$Q$131,MATCH($B34,$B$111:$B$131,0),MATCH(C$2,$B$111:$Q$111,0)) -> 3200 | D34: {=INDEX($B$111:$Q$131,MATCH($B34,$B$111:$B$131,0),COLUMN($D$2))} -> 0.17035 | E34: =C34*D34 -> 545.12 | F34: =INDEX($B$111:$Q$131,MATCH($B34,$B$111:$B$131,0),MATCH(F$2,$B$111:$Q$111,0)) -> 32.112709 | G34: =INDEX($B$111:$Q$131,MATCH($B34,$B$111:$B$131,0),MATCH(G$2,$B$111:$Q$111,0)) -> 19.443643 | H34: =INDEX($B$111:$Q$131,MATCH($B34,$B$111:$B$131,0),MATCH(H$2,$B$111:$Q$111,0)) -> 0.77574029 | I34: =INDEX($B$111:$Q$131,MATCH($B34,$B$111:$B$131,0),MATCH(I$2,$B$111:$Q$111,0)) -> 24.82919 | J34: =IFERROR(K34/K42*100,) -> 0 | K34: 0 | L34: {=LOOKUP(1,0/($B$111:$B$131=$B34),$L$111:$L$131)} -> 100 | M34: 0 | N34: =IF(P34>0,INDEX($B$111:$Z$131,MATCH(B34,$B$111:$B$131,0),MATCH($Z$111,$B$111:$Z$111,0))*C34*K34,C34*D34*K34) -> 0 | O34: =P34*K34 -> 0 | P34: {=INDEX($B$111:$AF$131,MATCH($B34,$B$111:$B$131,0),COLUMN($AA$111))} -> 100.32 | Q34: =SUM(N34:O34) -> 0 | S34: 水分% | T34: =F90 -> 0 | U34: =IF(A77>0,20,0) -> 0 | V34: 0 | Z34: 石粉耗用量 | AA34: 万吨 | AB34: =I25 -> 1.3584836 | AC34: =I49 -> 0.2871154 | AD34: =I73 -> 0 | AF34: =SUM(AB34:AE34) -> 1.645599
A35: =(SUMIF($B$27:$B$41,$B$112,$K$27:$K$41)+SUMIF($B$27:$B$41,$B$113,$K$27:$K$41)+SUMIF($B$27:$B$41,$B$114,$K$27:$K$41)+SUMIF($B$27:$B$41,$B$115,$K$27:$K$41))/$K$42*100 -> 0 | B35: =$B$120 -> 褐煤35（港2） | C35: =INDEX($B$111:$Q$131,MATCH($B35,$B$111:$B$131,0),MATCH(C$2,$B$111:$Q$111,0)) -> 3500 | D35: {=INDEX($B$111:$Q$131,MATCH($B35,$B$111:$B$131,0),COLUMN($D$2))} -> 0.17456286 | E35: =C35*D35 -> 610.97 | F35: =INDEX($B$111:$Q$131,MATCH($B35,$B$111:$B$131,0),MATCH(F$2,$B$111:$Q$111,0)) -> 29.814059 | G35: =INDEX($B$111:$Q$131,MATCH($B35,$B$111:$B$131,0),MATCH(G$2,$B$111:$Q$111,0)) -> 17.717186 | H35: =INDEX($B$111:$Q$131,MATCH($B35,$B$111:$B$131,0),MATCH(H$2,$B$111:$Q$111,0)) -> 0.78167601 | I35: =INDEX($B$111:$Q$131,MATCH($B35,$B$111:$B$131,0),MATCH(I$2,$B$111:$Q$111,0)) -> 26.875931 | J35: =IFERROR(K35/K42*100,) -> 0 | K35: 0 | L35: {=LOOKUP(1,0/($B$111:$B$131=$B35),$L$111:$L$131)} -> 100 | M35: 0 | N35: =IF(P35>0,INDEX($B$111:$Z$131,MATCH(B35,$B$111:$B$131,0),MATCH($Z$111,$B$111:$Z$111,0))*C35*K35,C35*D35*K35) -> 0 | O35: =P35*K35 -> 0 | P35: {=INDEX($B$111:$AF$131,MATCH($B35,$B$111:$B$131,0),COLUMN($AA$111))} -> 100.32 | Q35: =SUM(N35:O35) -> 0 | T35: 0 | U35: 0 | V35: 0 | Z35: 尿素耗用量 | AA35: 万吨 | AB35: =I26 -> 0 | AC35: =I50 -> 0.028516892 | AD35: =I74 -> 0 | AE35: =I98 -> 0 | AF35: =SUM(AB35:AE35) -> 0.028516892
A36: 利润（万元） | B36: =$B$121 -> 褐煤38（港3） | C36: =INDEX($B$111:$Q$131,MATCH($B36,$B$111:$B$131,0),MATCH(C$2,$B$111:$Q$111,0)) -> 3800 | D36: {=INDEX($B$111:$Q$131,MATCH($B36,$B$111:$B$131,0),COLUMN($D$2))} -> 0.1707 | E36: =C36*D36 -> 648.66 | F36: =INDEX($B$111:$Q$131,MATCH($B36,$B$111:$B$131,0),MATCH(F$2,$B$111:$Q$111,0)) -> 34.679691 | G36: =INDEX($B$111:$Q$131,MATCH($B36,$B$111:$B$131,0),MATCH(G$2,$B$111:$Q$111,0)) -> 8.6727633 | H36: =INDEX($B$111:$Q$131,MATCH($B36,$B$111:$B$131,0),MATCH(H$2,$B$111:$Q$111,0)) -> 0.82970573 | I36: =INDEX($B$111:$Q$131,MATCH($B36,$B$111:$B$131,0),MATCH(I$2,$B$111:$Q$111,0)) -> 28.638706 | J36: =IFERROR(K36/K42*100,) -> 0 | K36: 0 | L36: {=LOOKUP(1,0/($B$111:$B$131=$B36),$L$111:$L$131)} -> 100 | M36: 0 | N36: =IF(P36>0,INDEX($B$111:$Z$131,MATCH(B36,$B$111:$B$131,0),MATCH($Z$111,$B$111:$Z$111,0))*C36*K36,C36*D36*K36) -> 0 | O36: =P36*K36 -> 0 | P36: {=INDEX($B$111:$AF$131,MATCH($B36,$B$111:$B$131,0),COLUMN($AA$111))} -> 100.32 | Q36: =SUM(N36:O36) -> 0 | T36: 0 | U36: 0 | V36: 0 | Z36: 液氨耗用量 | AA36: 万吨 | AE36: =I97 -> 0 | AF36: =SUM(AB36:AE36) -> 0
A37: =C106 -> 4396.9912 | B37: =$B$122 -> 褐煤46 | C37: =INDEX($B$111:$Q$131,MATCH($B37,$B$111:$B$131,0),MATCH(C$2,$B$111:$Q$111,0)) -> 4600 | D37: {=INDEX($B$111:$Q$131,MATCH($B37,$B$111:$B$131,0),COLUMN($D$2))} -> 0.1625087 | E37: =C37*D37 -> 747.54 | F37: =INDEX($B$111:$Q$131,MATCH($B37,$B$111:$B$131,0),MATCH(F$2,$B$111:$Q$111,0)) -> 23.091665 | G37: =INDEX($B$111:$Q$131,MATCH($B37,$B$111:$B$131,0),MATCH(G$2,$B$111:$Q$111,0)) -> 10.878752 | H37: =INDEX($B$111:$Q$131,MATCH($B37,$B$111:$B$131,0),MATCH(H$2,$B$111:$Q$111,0)) -> 0.20812534 | I37: =INDEX($B$111:$Q$131,MATCH($B37,$B$111:$B$131,0),MATCH(I$2,$B$111:$Q$111,0)) -> 32.849465 | J37: =IFERROR(K37/K42*100,) -> 20.09734 | K37: 5.0304557 | L37: {=LOOKUP(1,0/($B$111:$B$131=$B37),$L$111:$L$131)} -> 100 | M37: 0 | N37: =IF(P37>0,INDEX($B$111:$Z$131,MATCH(B37,$B$111:$B$131,0),MATCH($Z$111,$B$111:$Z$111,0))*C37*K37,C37*D37*K37) -> 3255.8115 | O37: =P37*K37 -> 504.65531 | P37: {=INDEX($B$111:$AF$131,MATCH($B37,$B$111:$B$131,0),COLUMN($AA$111))} -> 100.32 | Q37: =SUM(N37:O37) -> 3760.4668 | T37: 0 | U37: 0 | V37: 0 | Z37: 炉灰价格 | AA37: 元/吨 | AB37: =K19 -> -20 | AC37: =K43 -> -45 | AD37: =K67 -> -20 | AE37: =K91 -> 20
A38: 锅炉效率（%） | B38: =$B$123 -> 烟煤55 | C38: =INDEX($B$111:$Q$131,MATCH($B38,$B$111:$B$131,0),MATCH(C$2,$B$111:$Q$111,0)) -> 5500 | D38: {=INDEX($B$111:$Q$131,MATCH($B38,$B$111:$B$131,0),COLUMN($D$2))} -> 0.16724 | E38: =C38*D38 -> 919.82 | F38: =INDEX($B$111:$Q$131,MATCH($B38,$B$111:$B$131,0),MATCH(F$2,$B$111:$Q$111,0)) -> 10.316451 | G38: =INDEX($B$111:$Q$131,MATCH($B38,$B$111:$B$131,0),MATCH(G$2,$B$111:$Q$111,0)) -> 19.875802 | H38: =INDEX($B$111:$Q$131,MATCH($B38,$B$111:$B$131,0),MATCH(H$2,$B$111:$Q$111,0)) -> 0.47663777 | I38: =INDEX($B$111:$Q$131,MATCH($B38,$B$111:$B$131,0),MATCH(I$2,$B$111:$Q$111,0)) -> 25.313893 | J38: =IFERROR(K38/K42*100,) -> 0 | K38: 0 | L38: {=LOOKUP(1,0/($B$111:$B$131=$B38),$L$111:$L$131)} -> 100 | M38: 0 | N38: =IF(P38>0,INDEX($B$111:$Z$131,MATCH(B38,$B$111:$B$131,0),MATCH($Z$111,$B$111:$Z$111,0))*C38*K38,C38*D38*K38) -> 0 | O38: =P38*K38 -> 0 | P38: {=INDEX($B$111:$AF$131,MATCH($B38,$B$111:$B$131,0),COLUMN($AA$111))} -> 100.32 | Q38: =SUM(N38:O38) -> 0 | T38: 0 | U38: 0 | V38: 0 | Z38: 炉渣价格 | AA38: 元/吨 | AB38: =K20 -> -8 | AC38: =K44 -> -20 | AD38: =K68 -> -8 | AE38: =K92 -> 0
A39: =AP205*100 -> 92.821233 | B39: =$B$124 -> 烟煤50备 | C39: =INDEX($B$111:$Q$131,MATCH($B39,$B$111:$B$131,0),MATCH(C$2,$B$111:$Q$111,0)) -> 5000 | D39: {=INDEX($B$111:$Q$131,MATCH($B39,$B$111:$B$131,0),COLUMN($D$2))} -> 0 | E39: =C39*D39 -> 0 | F39: =INDEX($B$111:$Q$131,MATCH($B39,$B$111:$B$131,0),MATCH(F$2,$B$111:$Q$111,0)) -> 0 | G39: =INDEX($B$111:$Q$131,MATCH($B39,$B$111:$B$131,0),MATCH(G$2,$B$111:$Q$111,0)) -> 0 | H39: =INDEX($B$111:$Q$131,MATCH($B39,$B$111:$B$131,0),MATCH(H$2,$B$111:$Q$111,0)) -> 0 | I39: =INDEX($B$111:$Q$131,MATCH($B39,$B$111:$B$131,0),MATCH(I$2,$B$111:$Q$111,0)) -> 0 | J39: =IFERROR(K39/K42*100,) -> 0 | K39: 0 | L39: {=LOOKUP(1,0/($B$111:$B$131=$B39),$L$111:$L$131)} -> 0 | M39: 0 | N39: =IF(P39>0,INDEX($B$111:$Z$131,MATCH(B39,$B$111:$B$131,0),MATCH($Z$111,$B$111:$Z$111,0))*C39*K39,C39*D39*K39) -> 0 | O39: =P39*K39 -> 0 | P39: {=INDEX($B$111:$AF$131,MATCH($B39,$B$111:$B$131,0),COLUMN($AA$111))} -> 0 | Q39: =SUM(N39:O39) -> 0 | T39: 0 | U39: 0 | V39: 0 | Z39: 石膏价格 | AA39: 元/吨 | AB39: =K21 -> -5 | AC39: =K45 -> -30 | AD39: =K69 -> -5
A40: 汽机热耗率 | B40: =$B$125 -> 烟煤55备 | C40: =INDEX($B$111:$Q$131,MATCH($B40,$B$111:$B$131,0),MATCH(C$2,$B$111:$Q$111,0)) -> 5500 | D40: {=INDEX($B$111:$Q$131,MATCH($B40,$B$111:$B$131,0),COLUMN($D$2))} -> 0 | E40: =C40*D40 -> 0 | F40: =INDEX($B$111:$Q$131,MATCH($B40,$B$111:$B$131,0),MATCH(F$2,$B$111:$Q$111,0)) -> 0 | G40: =INDEX($B$111:$Q$131,MATCH($B40,$B$111:$B$131,0),MATCH(G$2,$B$111:$Q$111,0)) -> 0 | H40: =INDEX($B$111:$Q$131,MATCH($B40,$B$111:$B$131,0),MATCH(H$2,$B$111:$Q$111,0)) -> 0 | I40: =INDEX($B$111:$Q$131,MATCH($B40,$B$111:$B$131,0),MATCH(I$2,$B$111:$Q$111,0)) -> 0 | J40: =IFERROR(K40/K42*100,) -> 0 | K40: 0 | L40: {=LOOKUP(1,0/($B$111:$B$131=$B40),$L$111:$L$131)} -> 0 | M40: 0 | N40: =IF(P40>0,INDEX($B$111:$Z$131,MATCH(B40,$B$111:$B$131,0),MATCH($Z$111,$B$111:$Z$111,0))*C40*K40,C40*D40*K40) -> 0 | O40: =P40*K40 -> 0 | P40: {=INDEX($B$111:$AF$131,MATCH($B40,$B$111:$B$131,0),COLUMN($AA$111))} -> 0 | Q40: =SUM(N40:O40) -> 0 | T40: 0 | U40: 0 | V40: 0 | Z40: 硫酸铵价格 | AA40: 元/吨 | AE40: =K93 -> 600
...

Sheet 煤参数
A1: 矿别及煤种 | B1: 收到基低位发热量 | C1: 收到基全水份 | D1: 收到基灰分 | E1: 收到基全硫 | F1: 收到基挥发份 | G1: 空气干燥基水份 | H1: 空气干燥基灰份 | I1: 空气干燥基全硫 | J1: 空气干燥基挥发份
B2: Qnet,ar 大卡 | C2: Mt.ar% | D2: Aar% | E2: St.ar% | F2: Var% | G2: Mad% | H2: Aad% | I2: St.ad% | J2: Vad%
A3: 东怀 | B3: 2376.38 | C3: 9.05 | D3: =H3*(100-$C3)/(100-$G3) -> 53.753421 | E3: =I3*(100-$C3)/(100-$G3) -> 1.5392982 | F3: =J3*(100-$C3)/(100-$G3) -> 20.240833 | G3: 3.1 | H3: 57.27 | I3: 1.64 | J3: 21.565
A4: 跃进 | B4: 1731.53 | C4: 9.9 | D4: =H4*(100-$C4)/(100-$G4) -> 59.606917 | E4: =I4*(100-$C4)/(100-$G4) -> 0.41611229 | F4: =J4*(100-$C4)/(100-$G4) -> 16.798781 | G4: 3.645 | H4: 63.745 | I4: 0.445 | J4: 17.965
A5: 褐煤2（云）长协 | B5: 2400 | C5: 19.2 | D5: =H5*(100-$C5)/(100-$G5) -> 32.974564 | E5: =I5*(100-$C5)/(100-$G5) -> 0.80500871 | F5: =J5*(100-$C5)/(100-$G5) -> 28.483232 | G5: 8.16 | H5: 37.48 | I5: 0.915 | J5: 32.375
A6: 褐煤3（云）长协 | B6: 3200 | C6: 19.15 | D6: =H6*(100-$C6)/(100-$G6) -> 23.873821 | E6: =I6*(100-$C6)/(100-$G6) -> 0.84706369 | F6: =J6*(100-$C6)/(100-$G6) -> 30.507667 | G6: 9.325 | H6: 26.775 | I6: 0.95 | J6: 34.215
A7: 褐煤3（云） | B7: 3200 | C7: 19.15 | D7: =H7*(100-$C7)/(100-$G7) -> 23.873821 | E7: =I7*(100-$C7)/(100-$G7) -> 0.84706369 | F7: =J7*(100-$C7)/(100-$G7) -> 30.507667 | G7: 9.325 | H7: 26.775 | I7: 0.95 | J7: 34.215
A8: 褐煤32（港1） | B8: 3200 | C8: 45 | D8: =H8*(100-$C8)/(100-$G8) -> 6.7073171 | E8: =I8*(100-$C8)/(100-$G8) -> 0.67073171 | F8: =J8*(100-$C8)/(100-$G8) -> 23.47561 | G8: 18 | H8: 10 | I8: 1 | J8: 35
A9: 褐煤35（港2） | B9: 3500 | C9: 40 | D9: =H9*(100-$C9)/(100-$G9) -> 5.8536585 | E9: =I9*(100-$C9)/(100-$G9) -> 0.73170732 | F9: =J9*(100-$C9)/(100-$G9) -> 25.609756 | G9: 18 | H9: 8 | I9: 1 | J9: 35
A10: 褐煤38（港3） | B10: 3800 | C10: 38 | D10: =H10*(100-$C10)/(100-$G10) -> 6.0487805 | E10: =I10*(100-$C10)/(100-$G10) -> 0.75609756 | F10: =J10*(100-$C10)/(100-$G10) -> 26.463415 | G10: 18 | H10: 8 | I10: 1 | J10: 35
A11: 褐煤47 | B11: 4700 | C11: 27 | D11: =H11*(100-$C11)/(100-$G11) -> 7.1219512 | E11: =I11*(100-$C11)/(100-$G11) -> 0.8902439 | F11: =J11*(100-$C11)/(100-$G11) -> 31.158537 | G11: 18 | H11: 8 | I11: 1 | J11: 35
A12: 烟煤55 | B12: 5500 | C12: 17 | D12: =H12*(100-$C12)/(100-$G12) -> 17.659574 | E12: =I12*(100-$C12)/(100-$G12) -> 0.70638298 | F12: =J12*(100-$C12)/(100-$G12) -> 24.723404 | G12: 6 | H12: 20 | I12: 0.8 | J12: 28
